[2022-11-13 21:11:37,651] {taskinstance.py:1179} INFO - Dependencies all met for <TaskInstance: run_webscrapers.run-webscraper-bravern manual__2022-11-13T21:06:22.807771+00:00 [queued]>
[2022-11-13 21:11:37,680] {taskinstance.py:1179} INFO - Dependencies all met for <TaskInstance: run_webscrapers.run-webscraper-bravern manual__2022-11-13T21:06:22.807771+00:00 [queued]>
[2022-11-13 21:11:37,685] {taskinstance.py:1376} INFO - 
--------------------------------------------------------------------------------
[2022-11-13 21:11:37,691] {taskinstance.py:1377} INFO - Starting attempt 2 of 2
[2022-11-13 21:11:37,693] {taskinstance.py:1378} INFO - 
--------------------------------------------------------------------------------
[2022-11-13 21:11:37,803] {taskinstance.py:1397} INFO - Executing <Task(DockerOperator): run-webscraper-bravern> on 2022-11-13 21:06:22.807771+00:00
[2022-11-13 21:11:37,811] {standard_task_runner.py:52} INFO - Started process 775 to run task
[2022-11-13 21:11:37,835] {standard_task_runner.py:79} INFO - Running: ['***', 'tasks', 'run', 'run_webscrapers', 'run-webscraper-bravern', 'manual__2022-11-13T21:06:22.807771+00:00', '--job-id', '11', '--raw', '--subdir', 'DAGS_FOLDER/run_webscraper.py', '--cfg-path', '/tmp/tmpkuc6gkv2', '--error-file', '/tmp/tmppb3c304k']
[2022-11-13 21:11:37,843] {standard_task_runner.py:80} INFO - Job 11: Subtask run-webscraper-bravern
[2022-11-13 21:11:38,002] {task_command.py:371} INFO - Running <TaskInstance: run_webscrapers.run-webscraper-bravern manual__2022-11-13T21:06:22.807771+00:00 [running]> on host c943e7c407a4
[2022-11-13 21:11:38,144] {taskinstance.py:1589} INFO - Exporting the following env vars:
AIRFLOW_CTX_DAG_OWNER=Airflow
AIRFLOW_CTX_DAG_ID=run_webscrapers
AIRFLOW_CTX_TASK_ID=run-webscraper-bravern
AIRFLOW_CTX_EXECUTION_DATE=2022-11-13T21:06:22.807771+00:00
AIRFLOW_CTX_TRY_NUMBER=2
AIRFLOW_CTX_DAG_RUN_ID=manual__2022-11-13T21:06:22.807771+00:00
[2022-11-13 21:11:38,265] {docker.py:248} INFO - Starting docker container from image domogordon/development:latest
[2022-11-13 21:11:38,289] {docker.py:258} WARNING - Using remote engine or docker-in-docker and mounting temporary volume from host is not supported. Falling back to `mount_tmp_dir=False` mode. You can set `mount_tmp_dir` parameter to False to disable mounting and remove the warning
[2022-11-13 21:11:41,959] {docker.py:310} INFO - Traceback (most recent call last):
  File "/usr/local/lib/python3.10/site-packages/urllib3/connectionpool.py", line 703, in urlopen
[2022-11-13 21:11:41,962] {docker.py:310} INFO - BRAVERN
Running Webscraper!
Scraping: https://www.thebravernapts.com/floorplans
[2022-11-13 21:11:41,972] {docker.py:310} INFO - httplib_response = self._make_request(
  File "/usr/local/lib/python3.10/site-packages/urllib3/connectionpool.py", line 449, in _make_request
[2022-11-13 21:11:41,974] {docker.py:310} INFO - six.raise_from(e, None)
  File "<string>", line 3, in raise_from
[2022-11-13 21:11:41,977] {docker.py:310} INFO - File "/usr/local/lib/python3.10/site-packages/urllib3/connectionpool.py", line 444, in _make_request
[2022-11-13 21:11:41,979] {docker.py:310} INFO - httplib_response = conn.getresponse()
  File "/usr/local/lib/python3.10/http/client.py", line 1374, in getresponse
[2022-11-13 21:11:41,985] {docker.py:310} INFO - response.begin()
[2022-11-13 21:11:41,989] {docker.py:310} INFO - File "/usr/local/lib/python3.10/http/client.py", line 318, in begin
[2022-11-13 21:11:41,991] {docker.py:310} INFO - version, status, reason = self._read_status()
[2022-11-13 21:11:41,995] {docker.py:310} INFO - File "/usr/local/lib/python3.10/http/client.py", line 287, in _read_status
[2022-11-13 21:11:41,997] {docker.py:310} INFO - raise RemoteDisconnected("Remote end closed connection without"
[2022-11-13 21:11:41,998] {docker.py:310} INFO - http.client.RemoteDisconnected: Remote end closed connection without response
[2022-11-13 21:11:42,002] {docker.py:310} INFO - During handling of the above exception, another exception occurred:
[2022-11-13 21:11:42,005] {docker.py:310} INFO - Traceback (most recent call last):
[2022-11-13 21:11:42,012] {docker.py:310} INFO - File "/app/main.py", line 120, in <module>
[2022-11-13 21:11:42,015] {docker.py:310} INFO - action_class.run()
[2022-11-13 21:11:42,021] {docker.py:310} INFO - File "/app/main.py", line 42, in run
[2022-11-13 21:11:42,024] {docker.py:310} INFO - self.connect()
[2022-11-13 21:11:42,029] {docker.py:310} INFO - File "/app/main.py", line 26, in connect
[2022-11-13 21:11:42,034] {docker.py:310} INFO - self.driver = webdriver.Remote(
[2022-11-13 21:11:42,041] {docker.py:310} INFO - File "/usr/local/lib/python3.10/site-packages/selenium/webdriver/remote/webdriver.py", line 272, in __init__
[2022-11-13 21:11:42,045] {docker.py:310} INFO - self.start_session(capabilities, browser_profile)
[2022-11-13 21:11:42,046] {docker.py:310} INFO - File "/usr/local/lib/python3.10/site-packages/selenium/webdriver/remote/webdriver.py", line 364, in start_session
[2022-11-13 21:11:42,049] {docker.py:310} INFO - response = self.execute(Command.NEW_SESSION, parameters)
[2022-11-13 21:11:42,051] {docker.py:310} INFO - File "/usr/local/lib/python3.10/site-packages/selenium/webdriver/remote/webdriver.py", line 427, in execute
[2022-11-13 21:11:42,053] {docker.py:310} INFO - response = self.command_executor.execute(driver_command, params)
[2022-11-13 21:11:42,055] {docker.py:310} INFO - File "/usr/local/lib/python3.10/site-packages/selenium/webdriver/remote/remote_connection.py", line 344, in execute
[2022-11-13 21:11:42,057] {docker.py:310} INFO - return self._request(command_info[0], url, body=data)
[2022-11-13 21:11:42,059] {docker.py:310} INFO - File "/usr/local/lib/python3.10/site-packages/selenium/webdriver/remote/remote_connection.py", line 366, in _request
[2022-11-13 21:11:42,061] {docker.py:310} INFO - response = self._conn.request(method, url, body=body, headers=headers)
[2022-11-13 21:11:42,064] {docker.py:310} INFO - File "/usr/local/lib/python3.10/site-packages/urllib3/request.py", line 78, in request
[2022-11-13 21:11:42,069] {docker.py:310} INFO - return self.request_encode_body(
[2022-11-13 21:11:42,073] {docker.py:310} INFO - File "/usr/local/lib/python3.10/site-packages/urllib3/request.py", line 170, in request_encode_body
[2022-11-13 21:11:42,077] {docker.py:310} INFO - return self.urlopen(method, url, **extra_kw)
[2022-11-13 21:11:42,081] {docker.py:310} INFO - File "/usr/local/lib/python3.10/site-packages/urllib3/poolmanager.py", line 376, in urlopen
[2022-11-13 21:11:42,083] {docker.py:310} INFO - response = conn.urlopen(method, u.request_uri, **kw)
[2022-11-13 21:11:42,087] {docker.py:310} INFO - File "/usr/local/lib/python3.10/site-packages/urllib3/connectionpool.py", line 787, in urlopen
[2022-11-13 21:11:42,091] {docker.py:310} INFO - retries = retries.increment(
  File "/usr/local/lib/python3.10/site-packages/urllib3/util/retry.py", line 550, in increment
[2022-11-13 21:11:42,094] {docker.py:310} INFO - raise six.reraise(type(error), error, _stacktrace)
[2022-11-13 21:11:42,096] {docker.py:310} INFO - File "/usr/local/lib/python3.10/site-packages/urllib3/packages/six.py", line 769, in reraise
[2022-11-13 21:11:42,098] {docker.py:310} INFO - raise value.with_traceback(tb)
[2022-11-13 21:11:42,100] {docker.py:310} INFO - File "/usr/local/lib/python3.10/site-packages/urllib3/connectionpool.py", line 703, in urlopen
[2022-11-13 21:11:42,106] {docker.py:310} INFO - httplib_response = self._make_request(
  File "/usr/local/lib/python3.10/site-packages/urllib3/connectionpool.py", line 449, in _make_request
[2022-11-13 21:11:42,108] {docker.py:310} INFO - six.raise_from(e, None)
[2022-11-13 21:11:42,110] {docker.py:310} INFO - File "<string>", line 3, in raise_from
[2022-11-13 21:11:42,114] {docker.py:310} INFO - File "/usr/local/lib/python3.10/site-packages/urllib3/connectionpool.py", line 444, in _make_request
[2022-11-13 21:11:42,117] {docker.py:310} INFO - httplib_response = conn.getresponse()
  File "/usr/local/lib/python3.10/http/client.py", line 1374, in getresponse
[2022-11-13 21:11:42,120] {docker.py:310} INFO - response.begin()
[2022-11-13 21:11:42,122] {docker.py:310} INFO - File "/usr/local/lib/python3.10/http/client.py", line 318, in begin
[2022-11-13 21:11:42,130] {docker.py:310} INFO - version, status, reason = self._read_status()
[2022-11-13 21:11:42,133] {docker.py:310} INFO - File "/usr/local/lib/python3.10/http/client.py", line 287, in _read_status
[2022-11-13 21:11:42,137] {docker.py:310} INFO - raise RemoteDisconnected("Remote end closed connection without"
urllib3.exceptions.ProtocolError: ('Connection aborted.', RemoteDisconnected('Remote end closed connection without response'))
[2022-11-13 21:11:42,459] {taskinstance.py:1909} ERROR - Task failed with exception
Traceback (most recent call last):
  File "/home/airflow/.local/lib/python3.9/site-packages/docker/api/client.py", line 268, in _raise_for_status
    response.raise_for_status()
  File "/home/airflow/.local/lib/python3.9/site-packages/requests/models.py", line 1022, in raise_for_status
    raise HTTPError(http_error_msg, response=self)
requests.exceptions.HTTPError: 400 Client Error: Bad Request for url: http://docker-proxy:2375/v1.41/containers/create

During handling of the above exception, another exception occurred:

Traceback (most recent call last):
  File "/home/airflow/.local/lib/python3.9/site-packages/airflow/providers/docker/operators/docker.py", line 255, in _run_image
    return self._run_image_with_mounts(self.mounts + [tmp_mount], add_tmp_variable=True)
  File "/home/airflow/.local/lib/python3.9/site-packages/airflow/providers/docker/operators/docker.py", line 278, in _run_image_with_mounts
    self.container = self.cli.create_container(
  File "/home/airflow/.local/lib/python3.9/site-packages/docker/api/container.py", line 428, in create_container
    return self.create_container_from_config(config, name)
  File "/home/airflow/.local/lib/python3.9/site-packages/docker/api/container.py", line 439, in create_container_from_config
    return self._result(res, True)
  File "/home/airflow/.local/lib/python3.9/site-packages/docker/api/client.py", line 274, in _result
    self._raise_for_status(response)
  File "/home/airflow/.local/lib/python3.9/site-packages/docker/api/client.py", line 270, in _raise_for_status
    raise create_api_error_from_http_exception(e)
  File "/home/airflow/.local/lib/python3.9/site-packages/docker/errors.py", line 31, in create_api_error_from_http_exception
    raise cls(e, response=response, explanation=explanation)
docker.errors.APIError: 400 Client Error for http://docker-proxy:2375/v1.41/containers/create: Bad Request ("invalid mount config for type "bind": bind source path does not exist: /tmp/airflowtmpsdv8y1_y")

During handling of the above exception, another exception occurred:

Traceback (most recent call last):
  File "/home/airflow/.local/lib/python3.9/site-packages/airflow/providers/docker/operators/docker.py", line 389, in execute
    return self._run_image()
  File "/home/airflow/.local/lib/python3.9/site-packages/airflow/providers/docker/operators/docker.py", line 264, in _run_image
    return self._run_image_with_mounts(self.mounts, add_tmp_variable=False)
  File "/home/airflow/.local/lib/python3.9/site-packages/airflow/providers/docker/operators/docker.py", line 315, in _run_image_with_mounts
    raise AirflowException(f'Docker container failed: {repr(result)} lines {joined_log_lines}')
airflow.exceptions.AirflowException: Docker container failed: {'Error': None, 'StatusCode': 1} lines Traceback (most recent call last):
  File "/usr/local/lib/python3.10/site-packages/urllib3/connectionpool.py", line 703, in urlopen
BRAVERN
Running Webscraper!
Scraping: https://www.thebravernapts.com/floorplans
httplib_response = self._make_request(
  File "/usr/local/lib/python3.10/site-packages/urllib3/connectionpool.py", line 449, in _make_request
six.raise_from(e, None)
  File "<string>", line 3, in raise_from
File "/usr/local/lib/python3.10/site-packages/urllib3/connectionpool.py", line 444, in _make_request
httplib_response = conn.getresponse()
  File "/usr/local/lib/python3.10/http/client.py", line 1374, in getresponse
response.begin()
File "/usr/local/lib/python3.10/http/client.py", line 318, in begin
version, status, reason = self._read_status()
File "/usr/local/lib/python3.10/http/client.py", line 287, in _read_status
raise RemoteDisconnected("Remote end closed connection without"
http.client.RemoteDisconnected: Remote end closed connection without response
During handling of the above exception, another exception occurred:
Traceback (most recent call last):
File "/app/main.py", line 120, in <module>
action_class.run()
File "/app/main.py", line 42, in run
self.connect()
File "/app/main.py", line 26, in connect
self.driver = webdriver.Remote(
File "/usr/local/lib/python3.10/site-packages/selenium/webdriver/remote/webdriver.py", line 272, in __init__
self.start_session(capabilities, browser_profile)
File "/usr/local/lib/python3.10/site-packages/selenium/webdriver/remote/webdriver.py", line 364, in start_session
response = self.execute(Command.NEW_SESSION, parameters)
File "/usr/local/lib/python3.10/site-packages/selenium/webdriver/remote/webdriver.py", line 427, in execute
response = self.command_executor.execute(driver_command, params)
File "/usr/local/lib/python3.10/site-packages/selenium/webdriver/remote/remote_connection.py", line 344, in execute
return self._request(command_info[0], url, body=data)
File "/usr/local/lib/python3.10/site-packages/selenium/webdriver/remote/remote_connection.py", line 366, in _request
response = self._conn.request(method, url, body=body, headers=headers)
File "/usr/local/lib/python3.10/site-packages/urllib3/request.py", line 78, in request
return self.request_encode_body(
File "/usr/local/lib/python3.10/site-packages/urllib3/request.py", line 170, in request_encode_body
return self.urlopen(method, url, **extra_kw)
File "/usr/local/lib/python3.10/site-packages/urllib3/poolmanager.py", line 376, in urlopen
response = conn.urlopen(method, u.request_uri, **kw)
File "/usr/local/lib/python3.10/site-packages/urllib3/connectionpool.py", line 787, in urlopen
retries = retries.increment(
  File "/usr/local/lib/python3.10/site-packages/urllib3/util/retry.py", line 550, in increment
raise six.reraise(type(error), error, _stacktrace)
File "/usr/local/lib/python3.10/site-packages/urllib3/packages/six.py", line 769, in reraise
raise value.with_traceback(tb)
File "/usr/local/lib/python3.10/site-packages/urllib3/connectionpool.py", line 703, in urlopen
httplib_response = self._make_request(
  File "/usr/local/lib/python3.10/site-packages/urllib3/connectionpool.py", line 449, in _make_request
six.raise_from(e, None)
File "<string>", line 3, in raise_from
File "/usr/local/lib/python3.10/site-packages/urllib3/connectionpool.py", line 444, in _make_request
httplib_response = conn.getresponse()
  File "/usr/local/lib/python3.10/http/client.py", line 1374, in getresponse
response.begin()
File "/usr/local/lib/python3.10/http/client.py", line 318, in begin
version, status, reason = self._read_status()
File "/usr/local/lib/python3.10/http/client.py", line 287, in _read_status
raise RemoteDisconnected("Remote end closed connection without"
urllib3.exceptions.ProtocolError: ('Connection aborted.', RemoteDisconnected('Remote end closed connection without response'))
[2022-11-13 21:11:42,488] {taskinstance.py:1415} INFO - Marking task as FAILED. dag_id=run_webscrapers, task_id=run-webscraper-bravern, execution_date=20221113T210622, start_date=20221113T211137, end_date=20221113T211142
[2022-11-13 21:11:42,526] {standard_task_runner.py:92} ERROR - Failed to execute job 11 for task run-webscraper-bravern (Docker container failed: {'Error': None, 'StatusCode': 1} lines Traceback (most recent call last):
  File "/usr/local/lib/python3.10/site-packages/urllib3/connectionpool.py", line 703, in urlopen
BRAVERN
Running Webscraper!
Scraping: https://www.thebravernapts.com/floorplans
httplib_response = self._make_request(
  File "/usr/local/lib/python3.10/site-packages/urllib3/connectionpool.py", line 449, in _make_request
six.raise_from(e, None)
  File "<string>", line 3, in raise_from
File "/usr/local/lib/python3.10/site-packages/urllib3/connectionpool.py", line 444, in _make_request
httplib_response = conn.getresponse()
  File "/usr/local/lib/python3.10/http/client.py", line 1374, in getresponse
response.begin()
File "/usr/local/lib/python3.10/http/client.py", line 318, in begin
version, status, reason = self._read_status()
File "/usr/local/lib/python3.10/http/client.py", line 287, in _read_status
raise RemoteDisconnected("Remote end closed connection without"
http.client.RemoteDisconnected: Remote end closed connection without response
During handling of the above exception, another exception occurred:
Traceback (most recent call last):
File "/app/main.py", line 120, in <module>
action_class.run()
File "/app/main.py", line 42, in run
self.connect()
File "/app/main.py", line 26, in connect
self.driver = webdriver.Remote(
File "/usr/local/lib/python3.10/site-packages/selenium/webdriver/remote/webdriver.py", line 272, in __init__
self.start_session(capabilities, browser_profile)
File "/usr/local/lib/python3.10/site-packages/selenium/webdriver/remote/webdriver.py", line 364, in start_session
response = self.execute(Command.NEW_SESSION, parameters)
File "/usr/local/lib/python3.10/site-packages/selenium/webdriver/remote/webdriver.py", line 427, in execute
response = self.command_executor.execute(driver_command, params)
File "/usr/local/lib/python3.10/site-packages/selenium/webdriver/remote/remote_connection.py", line 344, in execute
return self._request(command_info[0], url, body=data)
File "/usr/local/lib/python3.10/site-packages/selenium/webdriver/remote/remote_connection.py", line 366, in _request
response = self._conn.request(method, url, body=body, headers=headers)
File "/usr/local/lib/python3.10/site-packages/urllib3/request.py", line 78, in request
return self.request_encode_body(
File "/usr/local/lib/python3.10/site-packages/urllib3/request.py", line 170, in request_encode_body
return self.urlopen(method, url, **extra_kw)
File "/usr/local/lib/python3.10/site-packages/urllib3/poolmanager.py", line 376, in urlopen
response = conn.urlopen(method, u.request_uri, **kw)
File "/usr/local/lib/python3.10/site-packages/urllib3/connectionpool.py", line 787, in urlopen
retries = retries.increment(
  File "/usr/local/lib/python3.10/site-packages/urllib3/util/retry.py", line 550, in increment
raise six.reraise(type(error), error, _stacktrace)
File "/usr/local/lib/python3.10/site-packages/urllib3/packages/six.py", line 769, in reraise
raise value.with_traceback(tb)
File "/usr/local/lib/python3.10/site-packages/urllib3/connectionpool.py", line 703, in urlopen
httplib_response = self._make_request(
  File "/usr/local/lib/python3.10/site-packages/urllib3/connectionpool.py", line 449, in _make_request
six.raise_from(e, None)
File "<string>", line 3, in raise_from
File "/usr/local/lib/python3.10/site-packages/urllib3/connectionpool.py", line 444, in _make_request
httplib_response = conn.getresponse()
  File "/usr/local/lib/python3.10/http/client.py", line 1374, in getresponse
response.begin()
File "/usr/local/lib/python3.10/http/client.py", line 318, in begin
version, status, reason = self._read_status()
File "/usr/local/lib/python3.10/http/client.py", line 287, in _read_status
raise RemoteDisconnected("Remote end closed connection without"
urllib3.exceptions.ProtocolError: ('Connection aborted.', RemoteDisconnected('Remote end closed connection without response')); 775)
[2022-11-13 21:11:42,664] {local_task_job.py:156} INFO - Task exited with return code 1
[2022-11-13 21:11:42,745] {local_task_job.py:273} INFO - 0 downstream tasks scheduled from follow-on schedule check
