[2022-11-13 21:02:28,760] {taskinstance.py:1179} INFO - Dependencies all met for <TaskInstance: run_webscrapers.run-webscraper-bravern manual__2022-11-13T21:02:27.651804+00:00 [queued]>
[2022-11-13 21:02:28,769] {taskinstance.py:1179} INFO - Dependencies all met for <TaskInstance: run_webscrapers.run-webscraper-bravern manual__2022-11-13T21:02:27.651804+00:00 [queued]>
[2022-11-13 21:02:28,771] {taskinstance.py:1376} INFO - 
--------------------------------------------------------------------------------
[2022-11-13 21:02:28,774] {taskinstance.py:1377} INFO - Starting attempt 1 of 2
[2022-11-13 21:02:28,776] {taskinstance.py:1378} INFO - 
--------------------------------------------------------------------------------
[2022-11-13 21:02:28,788] {taskinstance.py:1397} INFO - Executing <Task(DockerOperator): run-webscraper-bravern> on 2022-11-13 21:02:27.651804+00:00
[2022-11-13 21:02:28,794] {standard_task_runner.py:52} INFO - Started process 370 to run task
[2022-11-13 21:02:28,797] {standard_task_runner.py:79} INFO - Running: ['***', 'tasks', 'run', 'run_webscrapers', 'run-webscraper-bravern', 'manual__2022-11-13T21:02:27.651804+00:00', '--job-id', '8', '--raw', '--subdir', 'DAGS_FOLDER/run_webscraper.py', '--cfg-path', '/tmp/tmpx88oxuke', '--error-file', '/tmp/tmpsb5e7z0l']
[2022-11-13 21:02:28,800] {standard_task_runner.py:80} INFO - Job 8: Subtask run-webscraper-bravern
[2022-11-13 21:02:28,869] {task_command.py:371} INFO - Running <TaskInstance: run_webscrapers.run-webscraper-bravern manual__2022-11-13T21:02:27.651804+00:00 [running]> on host c943e7c407a4
[2022-11-13 21:02:28,932] {taskinstance.py:1589} INFO - Exporting the following env vars:
AIRFLOW_CTX_DAG_OWNER=Airflow
AIRFLOW_CTX_DAG_ID=run_webscrapers
AIRFLOW_CTX_TASK_ID=run-webscraper-bravern
AIRFLOW_CTX_EXECUTION_DATE=2022-11-13T21:02:27.651804+00:00
AIRFLOW_CTX_TRY_NUMBER=1
AIRFLOW_CTX_DAG_RUN_ID=manual__2022-11-13T21:02:27.651804+00:00
[2022-11-13 21:02:28,978] {docker.py:248} INFO - Starting docker container from image domogordon/development:latest
[2022-11-13 21:02:29,004] {docker.py:258} WARNING - Using remote engine or docker-in-docker and mounting temporary volume from host is not supported. Falling back to `mount_tmp_dir=False` mode. You can set `mount_tmp_dir` parameter to False to disable mounting and remove the warning
[2022-11-13 21:02:45,742] {docker.py:310} INFO - BRAVERN
Running Webscraper!
Scraping: https://www.thebravernapts.com/floorplans
[2022-11-13 21:02:45,751] {docker.py:310} INFO - Traceback (most recent call last):
  File "/app/main.py", line 120, in <module>
[2022-11-13 21:02:45,757] {docker.py:310} INFO - action_class.run()
[2022-11-13 21:02:45,764] {docker.py:310} INFO - File "/app/main.py", line 42, in run
[2022-11-13 21:02:45,767] {docker.py:310} INFO - self.connect()
[2022-11-13 21:02:45,777] {docker.py:310} INFO - File "/app/main.py", line 26, in connect
[2022-11-13 21:02:45,783] {docker.py:310} INFO - self.driver = webdriver.Remote(
[2022-11-13 21:02:45,792] {docker.py:310} INFO - File "/usr/local/lib/python3.10/site-packages/selenium/webdriver/remote/webdriver.py", line 272, in __init__
[2022-11-13 21:02:45,798] {docker.py:310} INFO - self.start_session(capabilities, browser_profile)
[2022-11-13 21:02:45,805] {docker.py:310} INFO - File "/usr/local/lib/python3.10/site-packages/selenium/webdriver/remote/webdriver.py", line 364, in start_session
[2022-11-13 21:02:45,808] {docker.py:310} INFO - response = self.execute(Command.NEW_SESSION, parameters)
[2022-11-13 21:02:45,810] {docker.py:310} INFO - File "/usr/local/lib/python3.10/site-packages/selenium/webdriver/remote/webdriver.py", line 429, in execute
[2022-11-13 21:02:45,813] {docker.py:310} INFO - self.error_handler.check_response(response)
[2022-11-13 21:02:45,817] {docker.py:310} INFO - File "/usr/local/lib/python3.10/site-packages/selenium/webdriver/remote/errorhandler.py", line 243, in check_response
[2022-11-13 21:02:45,821] {docker.py:310} INFO - raise exception_class(message, screen, stacktrace)
selenium.common.exceptions.SessionNotCreatedException: Message: Could not start a new session. Could not start a new session. Error while creating session with the driver service. Stopping driver service: Could not start a new session. Response code 500. Message: unknown error: Chrome failed to start: crashed.
  (unknown error: unable to discover open pages)
  (The process started from chrome location /usr/bin/google-chrome is no longer running, so ChromeDriver is assuming that Chrome has crashed.) 
Host info: host: 'fe4c6bba287d', ip: '172.18.0.9'
Build info: version: '4.6.0', revision: '79f1c02ae20'
System info: os.name: 'Linux', os.arch: 'amd64', os.version: '5.10.104-linuxkit', java.version: '11.0.16'
Driver info: driver.version: unknown
Build info: version: '4.6.0', revision: '79f1c02ae20'
System info: os.name: 'Linux', os.arch: 'amd64', os.version: '5.10.104-linuxkit', java.version: '11.0.16'
Driver info: driver.version: unknown
Build info: version: '4.6.0', revision: '79f1c02ae20'
System info: os.name: 'Linux', os.arch: 'amd64', os.version: '5.10.104-linuxkit', java.version: '11.0.16'
Driver info: driver.version: unknown
Stacktrace:
    at org.openqa.selenium.grid.node.remote.RemoteNode.newSession (RemoteNode.java:150)
    at org.openqa.selenium.grid.distributor.local.LocalDistributor.startSession (LocalDistributor.java:645)
    at org.openqa.selenium.grid.distributor.local.LocalDistributor.newSession (LocalDistributor.java:564)
    at org.openqa.selenium.grid.distributor.local.LocalDistributor$NewSessionRunnable.handleNewSessionRequest (LocalDistributor.java:818)
    at org.openqa.selenium.grid.distributor.local.LocalDistributor$NewSessionRunnable.lambda$run$1 (LocalDistributor.java:779)
    at java.util.concurrent.ThreadPoolExecutor.runWorker (ThreadPoolExecutor.java:1128)
    at java.util.concurrent.ThreadPoolExecutor$Worker.run (ThreadPoolExecutor.java:628)
    at java.lang.Thread.run (Thread.java:829)
[2022-11-13 21:02:46,184] {taskinstance.py:1909} ERROR - Task failed with exception
Traceback (most recent call last):
  File "/home/airflow/.local/lib/python3.9/site-packages/docker/api/client.py", line 268, in _raise_for_status
    response.raise_for_status()
  File "/home/airflow/.local/lib/python3.9/site-packages/requests/models.py", line 1022, in raise_for_status
    raise HTTPError(http_error_msg, response=self)
requests.exceptions.HTTPError: 400 Client Error: Bad Request for url: http://docker-proxy:2375/v1.41/containers/create

During handling of the above exception, another exception occurred:

Traceback (most recent call last):
  File "/home/airflow/.local/lib/python3.9/site-packages/airflow/providers/docker/operators/docker.py", line 255, in _run_image
    return self._run_image_with_mounts(self.mounts + [tmp_mount], add_tmp_variable=True)
  File "/home/airflow/.local/lib/python3.9/site-packages/airflow/providers/docker/operators/docker.py", line 278, in _run_image_with_mounts
    self.container = self.cli.create_container(
  File "/home/airflow/.local/lib/python3.9/site-packages/docker/api/container.py", line 428, in create_container
    return self.create_container_from_config(config, name)
  File "/home/airflow/.local/lib/python3.9/site-packages/docker/api/container.py", line 439, in create_container_from_config
    return self._result(res, True)
  File "/home/airflow/.local/lib/python3.9/site-packages/docker/api/client.py", line 274, in _result
    self._raise_for_status(response)
  File "/home/airflow/.local/lib/python3.9/site-packages/docker/api/client.py", line 270, in _raise_for_status
    raise create_api_error_from_http_exception(e)
  File "/home/airflow/.local/lib/python3.9/site-packages/docker/errors.py", line 31, in create_api_error_from_http_exception
    raise cls(e, response=response, explanation=explanation)
docker.errors.APIError: 400 Client Error for http://docker-proxy:2375/v1.41/containers/create: Bad Request ("invalid mount config for type "bind": bind source path does not exist: /tmp/airflowtmpeo07johv")

During handling of the above exception, another exception occurred:

Traceback (most recent call last):
  File "/home/airflow/.local/lib/python3.9/site-packages/airflow/providers/docker/operators/docker.py", line 389, in execute
    return self._run_image()
  File "/home/airflow/.local/lib/python3.9/site-packages/airflow/providers/docker/operators/docker.py", line 264, in _run_image
    return self._run_image_with_mounts(self.mounts, add_tmp_variable=False)
  File "/home/airflow/.local/lib/python3.9/site-packages/airflow/providers/docker/operators/docker.py", line 315, in _run_image_with_mounts
    raise AirflowException(f'Docker container failed: {repr(result)} lines {joined_log_lines}')
airflow.exceptions.AirflowException: Docker container failed: {'Error': None, 'StatusCode': 1} lines BRAVERN
Running Webscraper!
Scraping: https://www.thebravernapts.com/floorplans
Traceback (most recent call last):
  File "/app/main.py", line 120, in <module>
action_class.run()
File "/app/main.py", line 42, in run
self.connect()
File "/app/main.py", line 26, in connect
self.driver = webdriver.Remote(
File "/usr/local/lib/python3.10/site-packages/selenium/webdriver/remote/webdriver.py", line 272, in __init__
self.start_session(capabilities, browser_profile)
File "/usr/local/lib/python3.10/site-packages/selenium/webdriver/remote/webdriver.py", line 364, in start_session
response = self.execute(Command.NEW_SESSION, parameters)
File "/usr/local/lib/python3.10/site-packages/selenium/webdriver/remote/webdriver.py", line 429, in execute
self.error_handler.check_response(response)
File "/usr/local/lib/python3.10/site-packages/selenium/webdriver/remote/errorhandler.py", line 243, in check_response
raise exception_class(message, screen, stacktrace)
selenium.common.exceptions.SessionNotCreatedException: Message: Could not start a new session. Could not start a new session. Error while creating session with the driver service. Stopping driver service: Could not start a new session. Response code 500. Message: unknown error: Chrome failed to start: crashed.
  (unknown error: unable to discover open pages)
  (The process started from chrome location /usr/bin/google-chrome is no longer running, so ChromeDriver is assuming that Chrome has crashed.) 
Host info: host: 'fe4c6bba287d', ip: '172.18.0.9'
Build info: version: '4.6.0', revision: '79f1c02ae20'
System info: os.name: 'Linux', os.arch: 'amd64', os.version: '5.10.104-linuxkit', java.version: '11.0.16'
Driver info: driver.version: unknown
Build info: version: '4.6.0', revision: '79f1c02ae20'
System info: os.name: 'Linux', os.arch: 'amd64', os.version: '5.10.104-linuxkit', java.version: '11.0.16'
Driver info: driver.version: unknown
Build info: version: '4.6.0', revision: '79f1c02ae20'
System info: os.name: 'Linux', os.arch: 'amd64', os.version: '5.10.104-linuxkit', java.version: '11.0.16'
Driver info: driver.version: unknown
Stacktrace:
    at org.openqa.selenium.grid.node.remote.RemoteNode.newSession (RemoteNode.java:150)
    at org.openqa.selenium.grid.distributor.local.LocalDistributor.startSession (LocalDistributor.java:645)
    at org.openqa.selenium.grid.distributor.local.LocalDistributor.newSession (LocalDistributor.java:564)
    at org.openqa.selenium.grid.distributor.local.LocalDistributor$NewSessionRunnable.handleNewSessionRequest (LocalDistributor.java:818)
    at org.openqa.selenium.grid.distributor.local.LocalDistributor$NewSessionRunnable.lambda$run$1 (LocalDistributor.java:779)
    at java.util.concurrent.ThreadPoolExecutor.runWorker (ThreadPoolExecutor.java:1128)
    at java.util.concurrent.ThreadPoolExecutor$Worker.run (ThreadPoolExecutor.java:628)
    at java.lang.Thread.run (Thread.java:829)
[2022-11-13 21:02:46,198] {taskinstance.py:1415} INFO - Marking task as UP_FOR_RETRY. dag_id=run_webscrapers, task_id=run-webscraper-bravern, execution_date=20221113T210227, start_date=20221113T210228, end_date=20221113T210246
[2022-11-13 21:02:46,223] {standard_task_runner.py:92} ERROR - Failed to execute job 8 for task run-webscraper-bravern (Docker container failed: {'Error': None, 'StatusCode': 1} lines BRAVERN
Running Webscraper!
Scraping: https://www.thebravernapts.com/floorplans
Traceback (most recent call last):
  File "/app/main.py", line 120, in <module>
action_class.run()
File "/app/main.py", line 42, in run
self.connect()
File "/app/main.py", line 26, in connect
self.driver = webdriver.Remote(
File "/usr/local/lib/python3.10/site-packages/selenium/webdriver/remote/webdriver.py", line 272, in __init__
self.start_session(capabilities, browser_profile)
File "/usr/local/lib/python3.10/site-packages/selenium/webdriver/remote/webdriver.py", line 364, in start_session
response = self.execute(Command.NEW_SESSION, parameters)
File "/usr/local/lib/python3.10/site-packages/selenium/webdriver/remote/webdriver.py", line 429, in execute
self.error_handler.check_response(response)
File "/usr/local/lib/python3.10/site-packages/selenium/webdriver/remote/errorhandler.py", line 243, in check_response
raise exception_class(message, screen, stacktrace)
selenium.common.exceptions.SessionNotCreatedException: Message: Could not start a new session. Could not start a new session. Error while creating session with the driver service. Stopping driver service: Could not start a new session. Response code 500. Message: unknown error: Chrome failed to start: crashed.
  (unknown error: unable to discover open pages)
  (The process started from chrome location /usr/bin/google-chrome is no longer running, so ChromeDriver is assuming that Chrome has crashed.) 
Host info: host: 'fe4c6bba287d', ip: '172.18.0.9'
Build info: version: '4.6.0', revision: '79f1c02ae20'
System info: os.name: 'Linux', os.arch: 'amd64', os.version: '5.10.104-linuxkit', java.version: '11.0.16'
Driver info: driver.version: unknown
Build info: version: '4.6.0', revision: '79f1c02ae20'
System info: os.name: 'Linux', os.arch: 'amd64', os.version: '5.10.104-linuxkit', java.version: '11.0.16'
Driver info: driver.version: unknown
Build info: version: '4.6.0', revision: '79f1c02ae20'
System info: os.name: 'Linux', os.arch: 'amd64', os.version: '5.10.104-linuxkit', java.version: '11.0.16'
Driver info: driver.version: unknown
Stacktrace:
    at org.openqa.selenium.grid.node.remote.RemoteNode.newSession (RemoteNode.java:150)
    at org.openqa.selenium.grid.distributor.local.LocalDistributor.startSession (LocalDistributor.java:645)
    at org.openqa.selenium.grid.distributor.local.LocalDistributor.newSession (LocalDistributor.java:564)
    at org.openqa.selenium.grid.distributor.local.LocalDistributor$NewSessionRunnable.handleNewSessionRequest (LocalDistributor.java:818)
    at org.openqa.selenium.grid.distributor.local.LocalDistributor$NewSessionRunnable.lambda$run$1 (LocalDistributor.java:779)
    at java.util.concurrent.ThreadPoolExecutor.runWorker (ThreadPoolExecutor.java:1128)
    at java.util.concurrent.ThreadPoolExecutor$Worker.run (ThreadPoolExecutor.java:628)
    at java.lang.Thread.run (Thread.java:829); 370)
[2022-11-13 21:02:46,264] {local_task_job.py:156} INFO - Task exited with return code 1
[2022-11-13 21:02:46,314] {local_task_job.py:273} INFO - 0 downstream tasks scheduled from follow-on schedule check
