[2022-11-13 20:22:03,045] {taskinstance.py:1179} INFO - Dependencies all met for <TaskInstance: run_webscrapers.run-webscraper-two_lincoln scheduled__2022-01-01T00:00:00+00:00 [queued]>
[2022-11-13 20:22:03,053] {taskinstance.py:1179} INFO - Dependencies all met for <TaskInstance: run_webscrapers.run-webscraper-two_lincoln scheduled__2022-01-01T00:00:00+00:00 [queued]>
[2022-11-13 20:22:03,055] {taskinstance.py:1376} INFO - 
--------------------------------------------------------------------------------
[2022-11-13 20:22:03,057] {taskinstance.py:1377} INFO - Starting attempt 2 of 3
[2022-11-13 20:22:03,058] {taskinstance.py:1378} INFO - 
--------------------------------------------------------------------------------
[2022-11-13 20:22:03,065] {taskinstance.py:1397} INFO - Executing <Task(DockerOperator): run-webscraper-two_lincoln> on 2022-01-01 00:00:00+00:00
[2022-11-13 20:22:03,071] {standard_task_runner.py:52} INFO - Started process 518 to run task
[2022-11-13 20:22:03,073] {standard_task_runner.py:79} INFO - Running: ['***', 'tasks', 'run', 'run_webscrapers', 'run-webscraper-two_lincoln', 'scheduled__2022-01-01T00:00:00+00:00', '--job-id', '5', '--raw', '--subdir', 'DAGS_FOLDER/run_webscraper.py', '--cfg-path', '/tmp/tmphkhqfi0o', '--error-file', '/tmp/tmp51twgoz_']
[2022-11-13 20:22:03,074] {standard_task_runner.py:80} INFO - Job 5: Subtask run-webscraper-two_lincoln
[2022-11-13 20:22:03,115] {task_command.py:371} INFO - Running <TaskInstance: run_webscrapers.run-webscraper-two_lincoln scheduled__2022-01-01T00:00:00+00:00 [running]> on host 113eb9d218de
[2022-11-13 20:22:03,151] {taskinstance.py:1589} INFO - Exporting the following env vars:
AIRFLOW_CTX_DAG_OWNER=Airflow
AIRFLOW_CTX_DAG_ID=run_webscrapers
AIRFLOW_CTX_TASK_ID=run-webscraper-two_lincoln
AIRFLOW_CTX_EXECUTION_DATE=2022-01-01T00:00:00+00:00
AIRFLOW_CTX_TRY_NUMBER=2
AIRFLOW_CTX_DAG_RUN_ID=scheduled__2022-01-01T00:00:00+00:00
[2022-11-13 20:22:03,184] {docker.py:248} INFO - Starting docker container from image domogordon/development:latest
[2022-11-13 20:22:03,205] {docker.py:258} WARNING - Using remote engine or docker-in-docker and mounting temporary volume from host is not supported. Falling back to `mount_tmp_dir=False` mode. You can set `mount_tmp_dir` parameter to False to disable mounting and remove the warning
[2022-11-13 20:22:10,139] {docker.py:310} INFO - TWO_LINCOLN
Running Webscraper!
Scraping: https://www.liveattwolincolntower.com/floorplans.aspx
[2022-11-13 20:22:10,143] {docker.py:310} INFO - Traceback (most recent call last):
  File "/app/main.py", line 120, in <module>
[2022-11-13 20:22:10,148] {docker.py:310} INFO - action_class.run()
  File "/app/main.py", line 42, in run
[2022-11-13 20:22:10,151] {docker.py:310} INFO - self.connect()
  File "/app/main.py", line 26, in connect
[2022-11-13 20:22:10,153] {docker.py:310} INFO - self.driver = webdriver.Remote(
  File "/usr/local/lib/python3.10/site-packages/selenium/webdriver/remote/webdriver.py", line 272, in __init__
[2022-11-13 20:22:10,155] {docker.py:310} INFO - self.start_session(capabilities, browser_profile)
[2022-11-13 20:22:10,156] {docker.py:310} INFO - File "/usr/local/lib/python3.10/site-packages/selenium/webdriver/remote/webdriver.py", line 364, in start_session
[2022-11-13 20:22:10,157] {docker.py:310} INFO - response = self.execute(Command.NEW_SESSION, parameters)
[2022-11-13 20:22:10,159] {docker.py:310} INFO - File "/usr/local/lib/python3.10/site-packages/selenium/webdriver/remote/webdriver.py", line 429, in execute
[2022-11-13 20:22:10,160] {docker.py:310} INFO - self.error_handler.check_response(response)
  File "/usr/local/lib/python3.10/site-packages/selenium/webdriver/remote/errorhandler.py", line 243, in check_response
    raise exception_class(message, screen, stacktrace)
selenium.common.exceptions.SessionNotCreatedException: Message: Could not start a new session. Could not start a new session. Error while creating session with the driver service. Stopping driver service: Could not start a new session. Response code 500. Message: unknown error: Chrome failed to start: crashed.
  (unknown error: DevToolsActivePort file doesn't exist)
  (The process started from chrome location /usr/bin/google-chrome is no longer running, so ChromeDriver is assuming that Chrome has crashed.) 
Host info: host: 'cdfe698fe0f4', ip: '172.20.0.7'
Build info: version: '4.6.0', revision: '79f1c02ae20'
System info: os.name: 'Linux', os.arch: 'amd64', os.version: '5.10.104-linuxkit', java.version: '11.0.16'
Driver info: driver.version: unknown
Build info: version: '4.6.0', revision: '79f1c02ae20'
System info: os.name: 'Linux', os.arch: 'amd64', os.version: '5.10.104-linuxkit', java.version: '11.0.16'
Driver info: driver.version: unknown
Build info: version: '4.6.0', revision: '79f1c02ae20'
System info: os.name: 'Linux', os.arch: 'amd64', os.version: '5.10.104-linuxkit', java.version: '11.0.16'
Driver info: driver.version: unknown
Stacktrace:
    at org.openqa.selenium.grid.node.remote.RemoteNode.newSession (RemoteNode.java:150)
    at org.openqa.selenium.grid.distributor.local.LocalDistributor.startSession (LocalDistributor.java:645)
    at org.openqa.selenium.grid.distributor.local.LocalDistributor.newSession (LocalDistributor.java:564)
    at org.openqa.selenium.grid.distributor.local.LocalDistributor$NewSessionRunnable.handleNewSessionRequest (LocalDistributor.java:818)
    at org.openqa.selenium.grid.distributor.local.LocalDistributor$NewSessionRunnable.lambda$run$1 (LocalDistributor.java:779)
    at java.util.concurrent.ThreadPoolExecutor.runWorker (ThreadPoolExecutor.java:1128)
    at java.util.concurrent.ThreadPoolExecutor$Worker.run (ThreadPoolExecutor.java:628)
    at java.lang.Thread.run (Thread.java:829)
[2022-11-13 20:22:10,411] {taskinstance.py:1909} ERROR - Task failed with exception
Traceback (most recent call last):
  File "/home/airflow/.local/lib/python3.9/site-packages/docker/api/client.py", line 268, in _raise_for_status
    response.raise_for_status()
  File "/home/airflow/.local/lib/python3.9/site-packages/requests/models.py", line 1022, in raise_for_status
    raise HTTPError(http_error_msg, response=self)
requests.exceptions.HTTPError: 400 Client Error: Bad Request for url: http://docker-proxy:2375/v1.41/containers/create

During handling of the above exception, another exception occurred:

Traceback (most recent call last):
  File "/home/airflow/.local/lib/python3.9/site-packages/airflow/providers/docker/operators/docker.py", line 255, in _run_image
    return self._run_image_with_mounts(self.mounts + [tmp_mount], add_tmp_variable=True)
  File "/home/airflow/.local/lib/python3.9/site-packages/airflow/providers/docker/operators/docker.py", line 278, in _run_image_with_mounts
    self.container = self.cli.create_container(
  File "/home/airflow/.local/lib/python3.9/site-packages/docker/api/container.py", line 428, in create_container
    return self.create_container_from_config(config, name)
  File "/home/airflow/.local/lib/python3.9/site-packages/docker/api/container.py", line 439, in create_container_from_config
    return self._result(res, True)
  File "/home/airflow/.local/lib/python3.9/site-packages/docker/api/client.py", line 274, in _result
    self._raise_for_status(response)
  File "/home/airflow/.local/lib/python3.9/site-packages/docker/api/client.py", line 270, in _raise_for_status
    raise create_api_error_from_http_exception(e)
  File "/home/airflow/.local/lib/python3.9/site-packages/docker/errors.py", line 31, in create_api_error_from_http_exception
    raise cls(e, response=response, explanation=explanation)
docker.errors.APIError: 400 Client Error for http://docker-proxy:2375/v1.41/containers/create: Bad Request ("invalid mount config for type "bind": bind source path does not exist: /tmp/airflowtmp99jk8kgd")

During handling of the above exception, another exception occurred:

Traceback (most recent call last):
  File "/home/airflow/.local/lib/python3.9/site-packages/airflow/providers/docker/operators/docker.py", line 389, in execute
    return self._run_image()
  File "/home/airflow/.local/lib/python3.9/site-packages/airflow/providers/docker/operators/docker.py", line 264, in _run_image
    return self._run_image_with_mounts(self.mounts, add_tmp_variable=False)
  File "/home/airflow/.local/lib/python3.9/site-packages/airflow/providers/docker/operators/docker.py", line 315, in _run_image_with_mounts
    raise AirflowException(f'Docker container failed: {repr(result)} lines {joined_log_lines}')
airflow.exceptions.AirflowException: Docker container failed: {'Error': None, 'StatusCode': 1} lines TWO_LINCOLN
Running Webscraper!
Scraping: https://www.liveattwolincolntower.com/floorplans.aspx
Traceback (most recent call last):
  File "/app/main.py", line 120, in <module>
action_class.run()
  File "/app/main.py", line 42, in run
self.connect()
  File "/app/main.py", line 26, in connect
self.driver = webdriver.Remote(
  File "/usr/local/lib/python3.10/site-packages/selenium/webdriver/remote/webdriver.py", line 272, in __init__
self.start_session(capabilities, browser_profile)
File "/usr/local/lib/python3.10/site-packages/selenium/webdriver/remote/webdriver.py", line 364, in start_session
response = self.execute(Command.NEW_SESSION, parameters)
File "/usr/local/lib/python3.10/site-packages/selenium/webdriver/remote/webdriver.py", line 429, in execute
self.error_handler.check_response(response)
  File "/usr/local/lib/python3.10/site-packages/selenium/webdriver/remote/errorhandler.py", line 243, in check_response
    raise exception_class(message, screen, stacktrace)
selenium.common.exceptions.SessionNotCreatedException: Message: Could not start a new session. Could not start a new session. Error while creating session with the driver service. Stopping driver service: Could not start a new session. Response code 500. Message: unknown error: Chrome failed to start: crashed.
  (unknown error: DevToolsActivePort file doesn't exist)
  (The process started from chrome location /usr/bin/google-chrome is no longer running, so ChromeDriver is assuming that Chrome has crashed.) 
Host info: host: 'cdfe698fe0f4', ip: '172.20.0.7'
Build info: version: '4.6.0', revision: '79f1c02ae20'
System info: os.name: 'Linux', os.arch: 'amd64', os.version: '5.10.104-linuxkit', java.version: '11.0.16'
Driver info: driver.version: unknown
Build info: version: '4.6.0', revision: '79f1c02ae20'
System info: os.name: 'Linux', os.arch: 'amd64', os.version: '5.10.104-linuxkit', java.version: '11.0.16'
Driver info: driver.version: unknown
Build info: version: '4.6.0', revision: '79f1c02ae20'
System info: os.name: 'Linux', os.arch: 'amd64', os.version: '5.10.104-linuxkit', java.version: '11.0.16'
Driver info: driver.version: unknown
Stacktrace:
    at org.openqa.selenium.grid.node.remote.RemoteNode.newSession (RemoteNode.java:150)
    at org.openqa.selenium.grid.distributor.local.LocalDistributor.startSession (LocalDistributor.java:645)
    at org.openqa.selenium.grid.distributor.local.LocalDistributor.newSession (LocalDistributor.java:564)
    at org.openqa.selenium.grid.distributor.local.LocalDistributor$NewSessionRunnable.handleNewSessionRequest (LocalDistributor.java:818)
    at org.openqa.selenium.grid.distributor.local.LocalDistributor$NewSessionRunnable.lambda$run$1 (LocalDistributor.java:779)
    at java.util.concurrent.ThreadPoolExecutor.runWorker (ThreadPoolExecutor.java:1128)
    at java.util.concurrent.ThreadPoolExecutor$Worker.run (ThreadPoolExecutor.java:628)
    at java.lang.Thread.run (Thread.java:829)
[2022-11-13 20:22:10,420] {taskinstance.py:1415} INFO - Marking task as UP_FOR_RETRY. dag_id=run_webscrapers, task_id=run-webscraper-two_lincoln, execution_date=20220101T000000, start_date=20221113T202203, end_date=20221113T202210
[2022-11-13 20:22:10,452] {standard_task_runner.py:92} ERROR - Failed to execute job 5 for task run-webscraper-two_lincoln (Docker container failed: {'Error': None, 'StatusCode': 1} lines TWO_LINCOLN
Running Webscraper!
Scraping: https://www.liveattwolincolntower.com/floorplans.aspx
Traceback (most recent call last):
  File "/app/main.py", line 120, in <module>
action_class.run()
  File "/app/main.py", line 42, in run
self.connect()
  File "/app/main.py", line 26, in connect
self.driver = webdriver.Remote(
  File "/usr/local/lib/python3.10/site-packages/selenium/webdriver/remote/webdriver.py", line 272, in __init__
self.start_session(capabilities, browser_profile)
File "/usr/local/lib/python3.10/site-packages/selenium/webdriver/remote/webdriver.py", line 364, in start_session
response = self.execute(Command.NEW_SESSION, parameters)
File "/usr/local/lib/python3.10/site-packages/selenium/webdriver/remote/webdriver.py", line 429, in execute
self.error_handler.check_response(response)
  File "/usr/local/lib/python3.10/site-packages/selenium/webdriver/remote/errorhandler.py", line 243, in check_response
    raise exception_class(message, screen, stacktrace)
selenium.common.exceptions.SessionNotCreatedException: Message: Could not start a new session. Could not start a new session. Error while creating session with the driver service. Stopping driver service: Could not start a new session. Response code 500. Message: unknown error: Chrome failed to start: crashed.
  (unknown error: DevToolsActivePort file doesn't exist)
  (The process started from chrome location /usr/bin/google-chrome is no longer running, so ChromeDriver is assuming that Chrome has crashed.) 
Host info: host: 'cdfe698fe0f4', ip: '172.20.0.7'
Build info: version: '4.6.0', revision: '79f1c02ae20'
System info: os.name: 'Linux', os.arch: 'amd64', os.version: '5.10.104-linuxkit', java.version: '11.0.16'
Driver info: driver.version: unknown
Build info: version: '4.6.0', revision: '79f1c02ae20'
System info: os.name: 'Linux', os.arch: 'amd64', os.version: '5.10.104-linuxkit', java.version: '11.0.16'
Driver info: driver.version: unknown
Build info: version: '4.6.0', revision: '79f1c02ae20'
System info: os.name: 'Linux', os.arch: 'amd64', os.version: '5.10.104-linuxkit', java.version: '11.0.16'
Driver info: driver.version: unknown
Stacktrace:
    at org.openqa.selenium.grid.node.remote.RemoteNode.newSession (RemoteNode.java:150)
    at org.openqa.selenium.grid.distributor.local.LocalDistributor.startSession (LocalDistributor.java:645)
    at org.openqa.selenium.grid.distributor.local.LocalDistributor.newSession (LocalDistributor.java:564)
    at org.openqa.selenium.grid.distributor.local.LocalDistributor$NewSessionRunnable.handleNewSessionRequest (LocalDistributor.java:818)
    at org.openqa.selenium.grid.distributor.local.LocalDistributor$NewSessionRunnable.lambda$run$1 (LocalDistributor.java:779)
    at java.util.concurrent.ThreadPoolExecutor.runWorker (ThreadPoolExecutor.java:1128)
    at java.util.concurrent.ThreadPoolExecutor$Worker.run (ThreadPoolExecutor.java:628)
    at java.lang.Thread.run (Thread.java:829); 518)
[2022-11-13 20:22:10,513] {local_task_job.py:156} INFO - Task exited with return code 1
[2022-11-13 20:22:10,561] {local_task_job.py:273} INFO - 0 downstream tasks scheduled from follow-on schedule check
[2022-11-13 21:01:00,650] {taskinstance.py:1179} INFO - Dependencies all met for <TaskInstance: run_webscrapers.run-webscraper-two_lincoln scheduled__2022-01-01T00:00:00+00:00 [queued]>
[2022-11-13 21:01:00,661] {taskinstance.py:1179} INFO - Dependencies all met for <TaskInstance: run_webscrapers.run-webscraper-two_lincoln scheduled__2022-01-01T00:00:00+00:00 [queued]>
[2022-11-13 21:01:00,663] {taskinstance.py:1376} INFO - 
--------------------------------------------------------------------------------
[2022-11-13 21:01:00,665] {taskinstance.py:1377} INFO - Starting attempt 2 of 2
[2022-11-13 21:01:00,667] {taskinstance.py:1378} INFO - 
--------------------------------------------------------------------------------
[2022-11-13 21:01:00,678] {taskinstance.py:1397} INFO - Executing <Task(DockerOperator): run-webscraper-two_lincoln> on 2022-01-01 00:00:00+00:00
[2022-11-13 21:01:00,684] {standard_task_runner.py:52} INFO - Started process 304 to run task
[2022-11-13 21:01:00,688] {standard_task_runner.py:79} INFO - Running: ['***', 'tasks', 'run', 'run_webscrapers', 'run-webscraper-two_lincoln', 'scheduled__2022-01-01T00:00:00+00:00', '--job-id', '5', '--raw', '--subdir', 'DAGS_FOLDER/run_webscraper.py', '--cfg-path', '/tmp/tmplc3ntagx', '--error-file', '/tmp/tmp0ov8msdb']
[2022-11-13 21:01:00,694] {standard_task_runner.py:80} INFO - Job 5: Subtask run-webscraper-two_lincoln
[2022-11-13 21:01:00,772] {task_command.py:371} INFO - Running <TaskInstance: run_webscrapers.run-webscraper-two_lincoln scheduled__2022-01-01T00:00:00+00:00 [running]> on host c943e7c407a4
[2022-11-13 21:01:00,862] {taskinstance.py:1589} INFO - Exporting the following env vars:
AIRFLOW_CTX_DAG_OWNER=Airflow
AIRFLOW_CTX_DAG_ID=run_webscrapers
AIRFLOW_CTX_TASK_ID=run-webscraper-two_lincoln
AIRFLOW_CTX_EXECUTION_DATE=2022-01-01T00:00:00+00:00
AIRFLOW_CTX_TRY_NUMBER=2
AIRFLOW_CTX_DAG_RUN_ID=scheduled__2022-01-01T00:00:00+00:00
[2022-11-13 21:01:00,950] {docker.py:248} INFO - Starting docker container from image domogordon/development:latest
[2022-11-13 21:01:00,987] {docker.py:258} WARNING - Using remote engine or docker-in-docker and mounting temporary volume from host is not supported. Falling back to `mount_tmp_dir=False` mode. You can set `mount_tmp_dir` parameter to False to disable mounting and remove the warning
[2022-11-13 21:01:10,823] {docker.py:310} INFO - TWO_LINCOLN
Running Webscraper!
Scraping: https://www.liveattwolincolntower.com/floorplans.aspx
[2022-11-13 21:01:10,832] {docker.py:310} INFO - Traceback (most recent call last):
[2022-11-13 21:01:10,835] {docker.py:310} INFO - File "/app/main.py", line 120, in <module>
[2022-11-13 21:01:10,840] {docker.py:310} INFO - action_class.run()
[2022-11-13 21:01:10,843] {docker.py:310} INFO - File "/app/main.py", line 42, in run
[2022-11-13 21:01:10,846] {docker.py:310} INFO - self.connect()
[2022-11-13 21:01:10,848] {docker.py:310} INFO - File "/app/main.py", line 26, in connect
[2022-11-13 21:01:10,852] {docker.py:310} INFO - self.driver = webdriver.Remote(
[2022-11-13 21:01:10,861] {docker.py:310} INFO - File "/usr/local/lib/python3.10/site-packages/selenium/webdriver/remote/webdriver.py", line 272, in __init__
[2022-11-13 21:01:10,866] {docker.py:310} INFO - self.start_session(capabilities, browser_profile)
  File "/usr/local/lib/python3.10/site-packages/selenium/webdriver/remote/webdriver.py", line 364, in start_session
[2022-11-13 21:01:10,873] {docker.py:310} INFO - response = self.execute(Command.NEW_SESSION, parameters)
[2022-11-13 21:01:10,876] {docker.py:310} INFO - File "/usr/local/lib/python3.10/site-packages/selenium/webdriver/remote/webdriver.py", line 429, in execute
[2022-11-13 21:01:10,886] {docker.py:310} INFO - self.error_handler.check_response(response)
[2022-11-13 21:01:10,891] {docker.py:310} INFO - File "/usr/local/lib/python3.10/site-packages/selenium/webdriver/remote/errorhandler.py", line 243, in check_response
[2022-11-13 21:01:10,893] {docker.py:310} INFO - raise exception_class(message, screen, stacktrace)
[2022-11-13 21:01:10,895] {docker.py:310} INFO - selenium.common.exceptions.SessionNotCreatedException: Message: Could not start a new session. Could not start a new session. Error while creating session with the driver service. Stopping driver service: Could not start a new session. Response code 500. Message: unknown error: Chrome failed to start: crashed.
  (unknown error: DevToolsActivePort file doesn't exist)
  (The process started from chrome location /usr/bin/google-chrome is no longer running, so ChromeDriver is assuming that Chrome has crashed.) 
Host info: host: 'fe4c6bba287d', ip: '172.18.0.9'
Build info: version: '4.6.0', revision: '79f1c02ae20'
System info: os.name: 'Linux', os.arch: 'amd64', os.version: '5.10.104-linuxkit', java.version: '11.0.16'
Driver info: driver.version: unknown
Build info: version: '4.6.0', revision: '79f1c02ae20'
System info: os.name: 'Linux', os.arch: 'amd64', os.version: '5.10.104-linuxkit', java.version: '11.0.16'
Driver info: driver.version: unknown
Build info: version: '4.6.0', revision: '79f1c02ae20'
System info: os.name: 'Linux', os.arch: 'amd64', os.version: '5.10.104-linuxkit', java.version: '11.0.16'
Driver info: driver.version: unknown
Stacktrace:
    at org.openqa.selenium.grid.node.remote.RemoteNode.newSession (RemoteNode.java:150)
    at org.openqa.selenium.grid.distributor.local.LocalDistributor.startSession (LocalDistributor.java:645)
    at org.openqa.selenium.grid.distributor.local.LocalDistributor.newSession (LocalDistributor.java:564)
    at org.openqa.selenium.grid.distributor.local.LocalDistributor$NewSessionRunnable.handleNewSessionRequest (LocalDistributor.java:818)
    at org.openqa.selenium.grid.distributor.local.LocalDistributor$NewSessionRunnable.lambda$run$1 (LocalDistributor.java:779)
    at java.util.concurrent.ThreadPoolExecutor.runWorker (ThreadPoolExecutor.java:1128)
    at java.util.concurrent.ThreadPoolExecutor$Worker.run (ThreadPoolExecutor.java:628)
    at java.lang.Thread.run (Thread.java:829)
[2022-11-13 21:01:10,902] {docker.py:310} INFO - 
[2022-11-13 21:01:11,681] {taskinstance.py:1909} ERROR - Task failed with exception
Traceback (most recent call last):
  File "/home/airflow/.local/lib/python3.9/site-packages/docker/api/client.py", line 268, in _raise_for_status
    response.raise_for_status()
  File "/home/airflow/.local/lib/python3.9/site-packages/requests/models.py", line 1022, in raise_for_status
    raise HTTPError(http_error_msg, response=self)
requests.exceptions.HTTPError: 400 Client Error: Bad Request for url: http://docker-proxy:2375/v1.41/containers/create

During handling of the above exception, another exception occurred:

Traceback (most recent call last):
  File "/home/airflow/.local/lib/python3.9/site-packages/airflow/providers/docker/operators/docker.py", line 255, in _run_image
    return self._run_image_with_mounts(self.mounts + [tmp_mount], add_tmp_variable=True)
  File "/home/airflow/.local/lib/python3.9/site-packages/airflow/providers/docker/operators/docker.py", line 278, in _run_image_with_mounts
    self.container = self.cli.create_container(
  File "/home/airflow/.local/lib/python3.9/site-packages/docker/api/container.py", line 428, in create_container
    return self.create_container_from_config(config, name)
  File "/home/airflow/.local/lib/python3.9/site-packages/docker/api/container.py", line 439, in create_container_from_config
    return self._result(res, True)
  File "/home/airflow/.local/lib/python3.9/site-packages/docker/api/client.py", line 274, in _result
    self._raise_for_status(response)
  File "/home/airflow/.local/lib/python3.9/site-packages/docker/api/client.py", line 270, in _raise_for_status
    raise create_api_error_from_http_exception(e)
  File "/home/airflow/.local/lib/python3.9/site-packages/docker/errors.py", line 31, in create_api_error_from_http_exception
    raise cls(e, response=response, explanation=explanation)
docker.errors.APIError: 400 Client Error for http://docker-proxy:2375/v1.41/containers/create: Bad Request ("invalid mount config for type "bind": bind source path does not exist: /tmp/airflowtmpvzc596v0")

During handling of the above exception, another exception occurred:

Traceback (most recent call last):
  File "/home/airflow/.local/lib/python3.9/site-packages/airflow/providers/docker/operators/docker.py", line 389, in execute
    return self._run_image()
  File "/home/airflow/.local/lib/python3.9/site-packages/airflow/providers/docker/operators/docker.py", line 264, in _run_image
    return self._run_image_with_mounts(self.mounts, add_tmp_variable=False)
  File "/home/airflow/.local/lib/python3.9/site-packages/airflow/providers/docker/operators/docker.py", line 315, in _run_image_with_mounts
    raise AirflowException(f'Docker container failed: {repr(result)} lines {joined_log_lines}')
airflow.exceptions.AirflowException: Docker container failed: {'Error': None, 'StatusCode': 1} lines TWO_LINCOLN
Running Webscraper!
Scraping: https://www.liveattwolincolntower.com/floorplans.aspx
Traceback (most recent call last):
File "/app/main.py", line 120, in <module>
action_class.run()
File "/app/main.py", line 42, in run
self.connect()
File "/app/main.py", line 26, in connect
self.driver = webdriver.Remote(
File "/usr/local/lib/python3.10/site-packages/selenium/webdriver/remote/webdriver.py", line 272, in __init__
self.start_session(capabilities, browser_profile)
  File "/usr/local/lib/python3.10/site-packages/selenium/webdriver/remote/webdriver.py", line 364, in start_session
response = self.execute(Command.NEW_SESSION, parameters)
File "/usr/local/lib/python3.10/site-packages/selenium/webdriver/remote/webdriver.py", line 429, in execute
self.error_handler.check_response(response)
File "/usr/local/lib/python3.10/site-packages/selenium/webdriver/remote/errorhandler.py", line 243, in check_response
raise exception_class(message, screen, stacktrace)
selenium.common.exceptions.SessionNotCreatedException: Message: Could not start a new session. Could not start a new session. Error while creating session with the driver service. Stopping driver service: Could not start a new session. Response code 500. Message: unknown error: Chrome failed to start: crashed.
  (unknown error: DevToolsActivePort file doesn't exist)
  (The process started from chrome location /usr/bin/google-chrome is no longer running, so ChromeDriver is assuming that Chrome has crashed.) 
Host info: host: 'fe4c6bba287d', ip: '172.18.0.9'
Build info: version: '4.6.0', revision: '79f1c02ae20'
System info: os.name: 'Linux', os.arch: 'amd64', os.version: '5.10.104-linuxkit', java.version: '11.0.16'
Driver info: driver.version: unknown
Build info: version: '4.6.0', revision: '79f1c02ae20'
System info: os.name: 'Linux', os.arch: 'amd64', os.version: '5.10.104-linuxkit', java.version: '11.0.16'
Driver info: driver.version: unknown
Build info: version: '4.6.0', revision: '79f1c02ae20'
System info: os.name: 'Linux', os.arch: 'amd64', os.version: '5.10.104-linuxkit', java.version: '11.0.16'
Driver info: driver.version: unknown
Stacktrace:
    at org.openqa.selenium.grid.node.remote.RemoteNode.newSession (RemoteNode.java:150)
    at org.openqa.selenium.grid.distributor.local.LocalDistributor.startSession (LocalDistributor.java:645)
    at org.openqa.selenium.grid.distributor.local.LocalDistributor.newSession (LocalDistributor.java:564)
    at org.openqa.selenium.grid.distributor.local.LocalDistributor$NewSessionRunnable.handleNewSessionRequest (LocalDistributor.java:818)
    at org.openqa.selenium.grid.distributor.local.LocalDistributor$NewSessionRunnable.lambda$run$1 (LocalDistributor.java:779)
    at java.util.concurrent.ThreadPoolExecutor.runWorker (ThreadPoolExecutor.java:1128)
    at java.util.concurrent.ThreadPoolExecutor$Worker.run (ThreadPoolExecutor.java:628)
    at java.lang.Thread.run (Thread.java:829)

[2022-11-13 21:01:11,714] {taskinstance.py:1415} INFO - Marking task as FAILED. dag_id=run_webscrapers, task_id=run-webscraper-two_lincoln, execution_date=20220101T000000, start_date=20221113T210100, end_date=20221113T210111
[2022-11-13 21:01:11,771] {standard_task_runner.py:92} ERROR - Failed to execute job 5 for task run-webscraper-two_lincoln (Docker container failed: {'Error': None, 'StatusCode': 1} lines TWO_LINCOLN
Running Webscraper!
Scraping: https://www.liveattwolincolntower.com/floorplans.aspx
Traceback (most recent call last):
File "/app/main.py", line 120, in <module>
action_class.run()
File "/app/main.py", line 42, in run
self.connect()
File "/app/main.py", line 26, in connect
self.driver = webdriver.Remote(
File "/usr/local/lib/python3.10/site-packages/selenium/webdriver/remote/webdriver.py", line 272, in __init__
self.start_session(capabilities, browser_profile)
  File "/usr/local/lib/python3.10/site-packages/selenium/webdriver/remote/webdriver.py", line 364, in start_session
response = self.execute(Command.NEW_SESSION, parameters)
File "/usr/local/lib/python3.10/site-packages/selenium/webdriver/remote/webdriver.py", line 429, in execute
self.error_handler.check_response(response)
File "/usr/local/lib/python3.10/site-packages/selenium/webdriver/remote/errorhandler.py", line 243, in check_response
raise exception_class(message, screen, stacktrace)
selenium.common.exceptions.SessionNotCreatedException: Message: Could not start a new session. Could not start a new session. Error while creating session with the driver service. Stopping driver service: Could not start a new session. Response code 500. Message: unknown error: Chrome failed to start: crashed.
  (unknown error: DevToolsActivePort file doesn't exist)
  (The process started from chrome location /usr/bin/google-chrome is no longer running, so ChromeDriver is assuming that Chrome has crashed.) 
Host info: host: 'fe4c6bba287d', ip: '172.18.0.9'
Build info: version: '4.6.0', revision: '79f1c02ae20'
System info: os.name: 'Linux', os.arch: 'amd64', os.version: '5.10.104-linuxkit', java.version: '11.0.16'
Driver info: driver.version: unknown
Build info: version: '4.6.0', revision: '79f1c02ae20'
System info: os.name: 'Linux', os.arch: 'amd64', os.version: '5.10.104-linuxkit', java.version: '11.0.16'
Driver info: driver.version: unknown
Build info: version: '4.6.0', revision: '79f1c02ae20'
System info: os.name: 'Linux', os.arch: 'amd64', os.version: '5.10.104-linuxkit', java.version: '11.0.16'
Driver info: driver.version: unknown
Stacktrace:
    at org.openqa.selenium.grid.node.remote.RemoteNode.newSession (RemoteNode.java:150)
    at org.openqa.selenium.grid.distributor.local.LocalDistributor.startSession (LocalDistributor.java:645)
    at org.openqa.selenium.grid.distributor.local.LocalDistributor.newSession (LocalDistributor.java:564)
    at org.openqa.selenium.grid.distributor.local.LocalDistributor$NewSessionRunnable.handleNewSessionRequest (LocalDistributor.java:818)
    at org.openqa.selenium.grid.distributor.local.LocalDistributor$NewSessionRunnable.lambda$run$1 (LocalDistributor.java:779)
    at java.util.concurrent.ThreadPoolExecutor.runWorker (ThreadPoolExecutor.java:1128)
    at java.util.concurrent.ThreadPoolExecutor$Worker.run (ThreadPoolExecutor.java:628)
    at java.lang.Thread.run (Thread.java:829)
; 304)
[2022-11-13 21:01:11,880] {local_task_job.py:156} INFO - Task exited with return code 1
[2022-11-13 21:01:12,001] {local_task_job.py:273} INFO - 0 downstream tasks scheduled from follow-on schedule check
